Workbook

Sheet Cover
B2: LAPORAN PENGUJIAN END-TO-END (E2E)
B3: Sistem Manajemen Gudang Tembakau - PR. SEKAR MAJU SEJAHTERA
B4: Dokumen Test Case Detail, Defect Log, Traceability Matrix & Execution Summary
B6: Repository | C6: https://github.com/FIrmansyxh/ERP-Sekar-Maju-Sejahtera
B7: Jenis Aplikasi | C7: Single Page Application (SPA) - React 19 + TypeScript + Vite (client-only, localStorage sbg persistence)
B8: Dokumen Acuan | C8: docs/E2E_TESTING_PREPARATION.md
B9: Disusun / Dieksekusi oleh | C9: Claude (AI QA Engineer) - Automated Browser Testing
B10: Tanggal Eksekusi | C10: 2026-09-13
B11: Environment Uji | C11: Local dev build (npm run dev), commit a1033d9; Browser: Chromium embedded (single browser); Viewport desktop standar
B12: Metode Eksekusi | C12: Pengujian fungsional aktif di browser sungguhan (bukan sekadar review dokumen) mengikuti Critical User Journey §5 dokumen acuan, dilengkapi code review bertarget untuk memverifikasi/mengklarifikasi temuan UI
B13: Status Entry Criteria | C13: npm run build & npm run lint (tsc --noEmit) LULUS tanpa error - lihat sheet 'Ringkasan Eksekusi'
B15: RINGKASAN TEMUAN UTAMA (lihat sheet Defect Log untuk detail lengkap)
B16: 2 Defect Blocker/Critical DITEMUKAN & TERBUKTI (dgn bukti reproduksi langsung di browser):
B17: - DEF-001 (Blocker): Sistem AUTO-LOGIN sebagai Super Admin tanpa kredensial saat localStorage kosong (bukan hanya "sesi hilang" seperti asumsi dokumen) - celah keamanan otentikasi.
B18: - DEF-002 (Critical): Potongan "Ganti Tikar" (Rp75.000) tercantum benar di rincian itemisasi Nota, namun TIDAK ikut dijumlahkan ke Total Potongan & Harga Final yang dibayar ke petani - petani berpotensi dibayar lebih besar dari seharusnya.
B19: 1 Defect Major: Audit Trail tidak auto-load data existing saat modul dibuka (DEF-003).
B20: Mesin kalkulasi PROFIT PENGIRIMAN (financialCalculations.ts) - bagian PALING KRITIKAL dari sistem ini - LULUS UJI dgn sangat akurat end-to-end (lihat TC-KIRIM-010).
B21: Dari 149 test case diturunkan dari checklist dokumen §6-7: 48 Pass, 10 Fail, 3 Blocked (kendala hardware), 88 Not Executed (di luar cakupan waktu sesi ini - lihat kolom "Catatan" tiap baris utk alasan spesifik & rekomendasi tindak lanjut).
B23: DAFTAR ISI WORKBOOK
B24: Ringkasan Eksekusi | C24: Dashboard rekap Pass/Fail/Not Executed per modul & prioritas, kriteria Exit
B25: Test Case Detail | C25: Seluruh 149 test case: ID, Modul, Precondition, Langkah, Expected, Actual, Status, Prioritas, Role Penguji
B26: Defect Log | C26: 8 temuan defect dgn severity, langkah reproduksi, dampak, rekomendasi
B27: Traceability Matrix | C27: Pemetaan Critical User Journey (§5 dokumen) ke test case terkait
B28: Sign-off | C28: Catatan persetujuan & status Exit Criteria untuk Product Owner

Sheet Test Case Detail
A1: ID Test Case | B1: Modul | C1: No. | D1: Skenario Pengujian | E1: Precondition | F1: Langkah Pengujian | G1: Expected Result | H1: Actual Result | I1: Status | J1: Prioritas | K1: Role Penguji | L1: Defect ID | M1: Catatan
A2: TC-AUTH-001 | B2: AUTH | C2: 1 | D2: Login sukses dengan akun default (7 akun) | E2: Browser dalam kondisi logout (erp_explicit_logout=true). Kredensial sesuai Lampiran 4.1. | F2: 1. Buka halaman login. 2. Input username & password akun target. 3. Klik 'Masuk ke Sistem ERP'. 4. Amati redirect & sidebar modul. | G2: Login berhasil, redirect ke modul-home, sidebar menampilkan modul sesuai role. | H2: Diuji 6 dari 7 akun (superadmin, adminsortir, admintimbang, adminkasir, adminpengiriman, kepalagudang) via tombol 'Akses Cepat Pengujian Role' & input manual. Semua berhasil login, redirect ke Dasbor Menu Utama, sidebar sesuai role. adminsortir_b (role sama dgn adminsortir) tidak diuji terpisah karena kredensial identik secara fungsi. | I2: Pass | J2: P0 | K2: Semua Role
A3: TC-AUTH-002 | B3: AUTH | C3: 2 | D3: Login dengan username salah | E3: Browser dalam kondisi logout. | F3: 1. Input username 'usersalah' (tidak terdaftar). 2. Input password apa saja. 3. Klik Masuk. | G3: Pesan error: 'Username atau email tidak terdaftar dalam sistem.' | H3: Pesan error tampil persis sesuai ekspektasi: 'Username atau email tidak terdaftar dalam sistem.' Tidak ada redirect / login berhasil. | I3: Pass | J3: P0 | K3: Guest
A4: TC-AUTH-003 | B4: AUTH | C4: 3 | D4: Login dengan password salah | E4: Username valid (superadmin), password salah. | F4: 1. Input username 'superadmin'. 2. Input password 'passwordsalah'. 3. Klik Masuk. | G4: Pesan error: 'Kata sandi (password) yang Anda masukkan salah.' | H4: Pesan error tampil persis sesuai ekspektasi. Login ditolak. | I4: Pass | J4: P0 | K4: Guest
A5: TC-AUTH-004 | B5: AUTH | C5: 4 | D5: Login dengan akun status_aktif=false | E5: Tersedia 1 akun user dengan status_aktif=false. | F5: 1. Input username/password akun nonaktif. 2. Klik Masuk. | G5: Pesan error akun dinonaktifkan, login ditolak. | H5: Tidak dieksekusi - tidak ada akun nonaktif tersedia di dataset demo; pembuatan akun nonaktif memerlukan modul Manajemen Pengguna yang tidak sempat diuji CRUD-nya di sesi ini. | I5: Not Executed | J5: P0 | K5: Guest
A6: TC-AUTH-005 | B6: AUTH | C6: 5 | D6: Login menggunakan email sebagai identifier | E6: Diketahui alamat email salah satu user (mis. rahmat.sulistyo@sekar...). | F6: 1. Input email pada field username. 2. Input password benar. 3. Klik Masuk. | G6: Login berhasil menggunakan email. | H6: Tidak dieksekusi pada sesi ini (waktu pengujian terbatas, diprioritaskan pada alur bisnis kritikal). | I6: Not Executed | J6: P1 | K6: Guest
A7: TC-AUTH-006 | B7: AUTH | C7: 6 | D7: Username/email case-insensitive | E7: Browser logout. | F7: 1. Input username 'SuperAdmin' (variasi kapitalisasi). 2. Input password 'admin123'. 3. Klik Masuk. | G7: Login berhasil walau kapitalisasi berbeda. | H7: Login berhasil dengan username 'SuperAdmin', redirect ke Dasbor Menu Utama sebagai Bpk. H. Rahmat Sulistyo (Super Admin). Case-insensitivity terbukti berfungsi. | I7: Pass | J7: P1 | K7: Guest
A8: TC-AUTH-007 | B8: AUTH | C8: 7 | D8: Validasi field kosong (username/password) | E8: Browser logout, kedua field kosong. | F8: 1. Kosongkan username & password. 2. Klik 'Masuk ke Sistem ERP'. | G8: Validasi form muncul, submit dicegah. | H8: Submit dicegah oleh validasi native HTML5 (atribut required=true terverifikasi pada kedua input via DOM inspection); tidak ada custom pesan validasi kustom ditampilkan, hanya browser-native constraint validation. | I8: Pass | J8: P1 | K8: Guest | M8: Rekomendasi: pertimbangkan pesan validasi kustom yang konsisten dgn gaya pesan error lain di form ini (bukan browser-native).
A9: TC-AUTH-008 | B9: AUTH | C9: 8 | D9: Refresh halaman (F5) setelah login, sesi tetap aktif | E9: User sudah login. | F9: 1. Login sebagai user manapun. 2. Tekan F5 / reload halaman. 3. Amati apakah sesi tetap login. | G9: Sesi tetap aktif, tidak logout paksa. | H9: Tidak diuji sebagai skenario terisolasi eksplisit pada sesi ini, namun perilaku ini teramati secara tidak langsung berkali-kali selama testing (banyak navigasi ke localhost:3000 dilakukan tanpa logout dan sesi selalu tetap aktif). | I9: Not Executed | J9: P0 | K9: Semua Role | M9: Perilaku teramati konsisten secara insidental; direkomendasikan uji eksplisit terpisah pada regresi berikutnya.
A10: TC-AUTH-009 | B10: AUTH | C10: 9 | D10: Logout eksplisit -> flag tersimpan -> refresh tidak auto-login | E10: User sudah login sebagai superadmin. | F10: 1. Klik menu akun > 'Keluar (Logout)'. 2. Amati redirect ke halaman login. 3. Reload/navigate ulang ke URL yang sama. | G10: Kembali ke Login View; localStorage erp_explicit_logout=true; refresh TIDAK auto-login kembali. | H10: Setelah klik Logout, halaman Login tampil (form username/password + tombol akses cepat role). Setelah navigate ulang ke http://localhost:3000, sistem TETAP menampilkan halaman Login (tidak auto-login). Perilaku sesuai ekspektasi dokumen. | I10: Pass | J10: P0 | K10: Semua Role
A11: TC-AUTH-010 | B11: AUTH | C11: 10 | D11: Tutup tab & buka tab baru tanpa logout | E11: User sudah login (belum logout eksplisit). | F11: 1. Buka tab baru ke URL yang sama. 2. Amati status sesi. | G11: Sesi tetap login di tab baru (localStorage shared antar tab origin sama). | H11: Tidak dieksekusi secara eksplisit pada sesi ini. | I11: Not Executed | J11: P1 | K11: Semua Role
A12: TC-AUTH-011 | B12: AUTH | C12: 11 | D12: Hapus localStorage manual -> auto-heal login sbg superadmin | E12: User login, kemudian seluruh localStorage dihapus via DevTools/Console. | F12: 1. Jalankan localStorage.clear() via console (mensimulasikan kondisi 'localStorage kosong' / first-time visit). 2. Reload/navigate ulang ke aplikasi. 3. Amati apakah muncul Login View atau auto-login. | G12: Dokumen meminta VERIFIKASI apakah perilaku ini disengaja (demo convenience) atau merupakan celah keamanan yang harus ditutup sebelum produksi. | H12: TEMUAN KEAMANAN KRITIKAL (lihat DEF-001). Setelah localStorage.clear() (mensimulasikan browser benar-benar baru / first-time visit, BUKAN sekadar 'sesi hilang tapi user aktif ada' seperti diasumsikan dokumen), aplikasi TIDAK PERNAH menampilkan Login View sama sekali - sistem langsung auto-login sebagai Super Admin (Bpk. H. Rahmat Sulistyo) dengan akses penuh tanpa kredensial apapun. Root cause: fungsi loadCurrentUser() di src/utils/storage.ts baris 173-180 melakukan fallback otomatis ke user superadmin aktif pertama setiap kali tidak ada sesi tersimpan DAN flag logout tidak di-set - kondisi ini juga terpenuhi pada kunjungan pertama kali (fresh browser), bukan hanya pada 'sesi hilang'. Ini adalah CELAH KEAMANAN, bukan hanya pertanyaan desain. | I12: Fail | J12: P0 | K12: Guest | L12: DEF-001 | M12: Blocker-level security defect. Wajib ditutup sebelum go-live produksi.
A13: TC-AUTH-012 | B13: AUTH | C13: 12 | D13: terakhir_login tercatat benar (ISO timestamp) | E13: User login sukses. | F13: 1. Login. 2. Cek field terakhir_login pada data user (via localStorage/DevTools). | G13: Timestamp ISO akurat sesuai waktu login. | H13: Tidak dieksekusi secara langsung (memerlukan inspeksi field data user mentah yang tidak diprioritaskan pada sesi ini). | I13: Not Executed | J13: P2 | K13: Guest
A14: TC-AUTH-013 | B14: AUTH | C14: 13 | D14: XSS pada field username/password | E14: Browser logout. | F14: 1. Input '<script>alert(1)</script>' pada field username. 2. Input teks bebas pada password. 3. Klik Masuk. 4. Amati apakah script tereksekusi (alert popup) dan bagaimana input diperlakukan. | G14: Input di-escape/tidak dieksekusi sebagai kode; ditolak sebagai username tidak valid. | H14: Payload XSS tidak tereksekusi (tidak ada alert popup, tidak ada error console terkait). React merender payload sebagai teks literal di dalam field. Sistem menganggapnya sebagai username tidak valid dan menampilkan pesan 'Username atau email tidak terdaftar dalam sistem.' Login form AMAN dari XSS reflected sederhana. | I14: Pass | J14: P0 | K14: Guest
A15: TC-AUTH-014 | B15: AUTH | C15: 14 | D15: Multi-tab: login user berbeda di tab berbeda | E15: 2 tab browser terbuka pada origin yang sama. | F15: 1. Tab 1: login sbg user A. 2. Tab 2: login sbg user B. 3. Amati sinkronisasi/konflik sesi antar tab. | G15: Perilaku sinkronisasi/konflik terverifikasi & terdokumentasi (localStorage dibagi antar tab origin sama, sehingga user B kemungkinan akan menimpa sesi tab 1 saat difokuskan ulang). | H15: Tidak dieksekusi pada sesi ini (memerlukan orkestrasi 2 tab paralel yang di luar cakupan waktu pengujian saat ini). | I15: Not Executed | J15: P1 | K15: Semua Role
A16: TC-RBAC-001 | B16: RBAC | C16: 1 | D16: Sidebar hanya tampilkan modul sesuai allowedModules per role | E16: Kredensial 7 role tersedia (lihat Lampiran 4.1/4.2). | F16: 1. Login sebagai masing-masing role. 2. Buka 'Menu Akses Anda' / sidebar. 3. Bandingkan daftar modul dengan Matriks Kapabilitas §4.2. | G16: Daftar modul persis sesuai matriks role. | H16: Diverifikasi untuk 6 role (superadmin=19 modul termasuk Manajemen Pengguna & Audit Trail; admin_sortir=13 modul termasuk Master Petani/Harga/Sortir tanpa Timbangan/Kasir/User; admin_timbang=HANYA 2 modul yaitu Home+Timbangan; admin_kasir=11 modul termasuk Sortir/Timbangan/Kasir/Laporan tanpa Master Data write/User; admin_pengiriman=6 modul yaitu Pengiriman Sample/DO/Status Batch/Harga Jual/Laporan Pengiriman; kepala_gudang=9 modul read-only Dashboard & seluruh Laporan + Status Batch). Seluruhnya PERSIS sesuai Matriks Kapabilitas §4.2 dokumen. | I16: Pass | J16: P0 | K16: Semua Role
A17: TC-RBAC-002 | B17: RBAC | C17: 2 | D17: Bypass modul terlarang via manipulasi localStorage active_module | E17: Login sebagai admin_timbang (role paling terbatas). | F17: 1. Login sbg admin_timbang. 2. Jalankan localStorage.setItem('erp_tembakau_active_module','modul-users') via console. 3. Reload/navigate ulang halaman. 4. Amati apakah modul-users (Manajemen Pengguna) berhasil diakses. | G17: Sistem redirect balik ke modul-home, TIDAK menampilkan konten modul terlarang. | H17: Setelah manipulasi localStorage dan reload, sistem TIDAK menampilkan modul Manajemen Pengguna - otomatis redirect kembali ke Dasbor Menu Utama (Home) sesuai hak akses admin_timbang yang sebenarnya. RBAC enforcement lolos uji bypass sederhana ini (defense-in-depth di luar hanya menyembunyikan menu UI). | I17: Pass | J17: P0 | K17: Admin Timbang
A18: TC-RBAC-003 | B18: RBAC | C18: 3 | D18: admin_timbang hanya bisa masuk modul Timbangan | E18: Login sebagai admin_timbang. | F18: 1. Login. 2. Amati seluruh sidebar & 'Menu Akses Anda'. | G18: Hanya menu Home & Timbangan yang ada/dapat diklik; modul lain benar-benar tidak ada (bukan sekadar disabled). | H18: Konfirmasi: 'Menu Akses Anda (Admin Timbang)' hanya menampilkan 2 baris: Home dan Timbangan ('Menampilkan 2 modul aktif sesuai wewenang peran Admin Timbang'). Tidak ada elemen menu lain yang dapat diklik sama sekali. | I18: Pass | J18: P0 | K18: Admin Timbang
A19: TC-RBAC-004 | B19: RBAC | C19: 4 | D19: kepala_gudang tidak bisa melakukan aksi tulis (create/edit/delete) | E19: Login sebagai kepala_gudang. | F19: 1. Login. 2. Amati seluruh modul yang tersedia (9 modul: Dashboard + 6 Laporan + Status Batch). 3. Pastikan tidak ada modul write (Sortir/Timbang/Kasir/Master Data/Pengiriman/User) yang bisa diakses. | G19: Hanya modul baca (laporan & dashboard) yang tersedia; tidak ada aksi tulis yang dapat dijangkau dari UI. | H19: Sidebar/menu kepala_gudang hanya berisi Dashboard Analytic + 6 modul Laporan (read-only) + Status & Detail Batch. Tidak satupun modul dengan kapabilitas create/edit/delete (Sortir, Timbangan, Kasir, Master Petani/Harga, Pengiriman, Manajemen User) muncul di menu, sehingga tidak ada aksi tulis yang terjangkau via UI normal. | I19: Pass | J19: P0 | K19: Kepala Gudang
A20: TC-RBAC-005 | B20: RBAC | C20: 5 | D20: Tombol 'Kelola User' & 'Audit Trail' hanya untuk superadmin | E20: Kredensial semua role tersedia. | F20: 1. Login sebagai masing-masing dari 6 role non-superadmin. 2. Cari elemen 'Kelola User'/'Manajemen Pengguna'/'Audit Trail' di UI. | G20: Elemen tersebut TIDAK muncul untuk role selain superadmin. | H20: Dikonfirmasi tidak ada satupun dari 6 role non-superadmin (admin_sortir, admin_timbang, admin_kasir, admin_pengiriman, kepala_gudang, dan varian adminsortir_b) yang menampilkan menu 'Manajemen Pengguna (RBAC)' atau 'Audit Trail'. Hanya superadmin yang memiliki modul ke-19 'Manajemen Pengguna (RBAC)' berisi kedua fitur tsb. | I20: Pass | J20: P0 | K20: Semua Role
A21: TC-RBAC-006 | B21: RBAC | C21: 6 | D21: Deactivate user yang sedang login di sesi lain -> kehilangan akses saat refresh | E21: 2 sesi browser, salah satu user dinonaktifkan superadmin dari sesi lain. | F21: 1. User A login di sesi 1. 2. Superadmin nonaktifkan user A dari sesi 2. 3. Refresh sesi 1. 4. Amati apakah user A kehilangan akses. | G21: Sesi user A kehilangan akses setelah refresh berikutnya. | H21: Tidak dieksekusi pada sesi ini (memerlukan 2 sesi paralel & modul CRUD User yang tidak sempat diuji). | I21: Not Executed | J21: P1 | K21: Superadmin
A22: TC-RBAC-007 | B22: RBAC | C22: 7 | D22: Role Matrix Modal identik dengan tabel dokumentasi §4.2 | E22: Login sebagai superadmin, buka 'Matriks Wewenang' pada modul Manajemen Pengguna. | F22: 1. Buka Manajemen Pengguna. 2. Klik tombol 'Matriks Wewenang'. 3. Bandingkan isi modal dengan tabel §4.2. | G22: Data pada modal identik dengan dokumentasi (tidak ada penyimpangan implementasi vs dokumen). | H22: Tidak dieksekusi - tombol 'Matriks Wewenang' teramati ada di UI Manajemen Pengguna namun tidak sempat dibuka/dibandingkan detail isinya pada sesi ini. Verifikasi tidak langsung (via observasi behavior 6 role di RBAC-001) menunjukkan behavior aktual KONSISTEN dgn §4.2. | I22: Not Executed | J22: P1 | K22: Superadmin
A23: TC-PETANI-001 | B23: PETANI | C23: 1 | D23: Tambah petani baru -> ID auto-generate PTN-YYYY-XXX berurutan | E23: Login sbg admin_sortir/superadmin. Jumlah petani existing diketahui (34). | F23: 1. Buka Master Petani. 2. Klik 'Tambah Petani Baru'. 3. Amati field 'ID Petani (Otomatis Sistem)'. | G23: ID otomatis terisi format PTN-YYYY-XXX, urut setelah ID terakhir (mis. 34 data -> ID baru 035). | H23: Field ID Petani otomatis terisi 'PTN-2026-035' (petani ke-35, setelah 34 data existing), format PTN-YYYY-XXX sesuai, tahun 2026 sesuai tanggal sistem (13-09-2026), field read-only/disabled tidak bisa diedit manual. | I23: Pass | J23: P0 | K23: Admin Sortir
A24: TC-PETANI-002 | B24: PETANI | C24: 2 | D24: Tambah petani dengan field wajib kosong | E24: Form Tambah Petani Baru terbuka, semua field kosong. | F24: 1. Klik 'Simpan Petani' tanpa mengisi apapun. | G24: Validasi muncul untuk Nama Petani, Nomor HP, dan Alamat Lengkap. | H24: Validasi inline muncul tepat di bawah masing-masing field: 'Nama petani wajib diisi (minimal 2 karakter).', 'Nomor HP wajib diisi (minimal 9 digit angka).', 'Alamat lengkap petani wajib diisi.' Submit dicegah. | I24: Pass | J24: P0 | K24: Admin Sortir
... A34: TC-PETANI-012 | B34: PETANI | C34: 12 | D34: Pagination tabel petani dengan >34 data | E34: 35 data petani tersedia (setelah PETANI-001). | F34: 1. Set 'Tampil per hal.' ke nilai kecil (10). 2. Navigasi halaman pertama/terakhir/pindah halaman. | G34: Pagination bekerja benar untuk >34 data. | H34: Tidak dieksekusi secara eksplisit; kontrol 'Tampil 10/25/50/100/250/500 per hal.' teramati tersedia di UI namun navigasi halaman tidak diuji langsung. | I34: Not Executed | J34: P2 | K34: Admin Sortir
A35: TC-PETANI-013 | B35: PETANI | C35: 13 | D35: Statistik petani (total_setoran_bal, total_berat_kg, grade_dominan) auto-update | E35: Transaksi baru untuk seorang petani baru selesai (Sortir->Timbang->Kasir). | F35: 1. Selesaikan 1 transaksi penuh untuk seorang petani. 2. Cek kolom statistik petani tsb di Master Petani/Detail Drawer. | G35: Statistik ter-update otomatis (Total Bal, dsb). | H35: Tidak diverifikasi secara eksplisit pasca transaksi KUP0001 selesai (3 bal, petani PTN-2026-035); kolom 'Total Bal' pada tabel Master Petani tidak dicek ulang setelah transaksi selesai pada sesi ini. | I35: Not Executed | J35: P0 | K35: Admin Sortir | M35: Rekomendasi: prioritaskan verifikasi ini pada siklus regresi berikutnya karena berdampak pada akurasi laporan Petani & Setoran.
A36: TC-PETANI-014 | B36: PETANI | C36: 14 | D36: Barcode scanner (HID keyboard wedge) memanggil data petani dgn benar | E36: Perangkat scanner fisik tersedia. | F36: 1. Scan barcode ID petani secara cepat berturut-turut (<50ms antar karakter, diakhiri Enter). 2. Amati data petani yang terpanggil. | G36: Data petani yang tepat terpanggil sesuai barcode yang discan. | H36: Tidak dapat dieksekusi - memerlukan perangkat hardware fisik (barcode scanner USB) yang tidak tersedia pada environment pengujian berbasis browser otomatis ini. | I36: Blocked | J36: P0 | K36: Admin Sortir/Timbang | M36: Memerlukan pengujian manual di perangkat loket fisik.
A37: TC-PETANI-015 | B37: PETANI | C37: 15 | D37: Input manual cepat (paste) tidak salah terdeteksi sbg scan barcode | E37: Field input No Bal / ID petani tersedia. | F37: 1. Paste teks cepat ke field yang BUKAN scanner-dedicated. 2. Amati apakah salah terdeteksi sbg scan. | G37: Tidak salah terdeteksi sebagai scan jika bukan dari field yang tepat. | H37: Tidak dapat dieksekusi sepenuhnya tanpa hardware scanner sungguhan untuk perbandingan; berkaitan dengan PETANI-014. | I37: Blocked | J37: P2 | K37: Admin Sortir/Timbang
A38: TC-HARGA-BELI-001 | B38: HARGA-BELI | C38: 1 | D38: Tambah harga grade baru | E38: Login superadmin/admin_sortir, buka Master Harga Beli. | F38: 1. Tambah entri grade baru (kode_grade, harga_per_kg, tanggal_berlaku). 2. Simpan. | G38: Entri baru tersimpan & tampil di daftar. | H38: Tidak dieksekusi pada sesi ini. Modul Master Harga Beli teramati berisi 41 kode grade (30-70) saat digunakan secara tidak langsung di modul Sortir. | I38: Not Executed | J38: P0 | K38: Admin Sortir
A39: TC-HARGA-BELI-002 | B39: HARGA-BELI | C39: 2 | D39: Ubah harga grade aktif -> riwayat tersimpan di HargaHistoryModal | E39: Data grade existing tersedia. | F39: 1. Ubah harga_per_kg suatu grade. 2. Buka riwayat perubahan (HargaHistoryModal). | G39: Riwayat perubahan tersimpan & dapat dilihat. | H39: Tidak dieksekusi pada sesi ini. | I39: Not Executed | J39: P0 | K39: Admin Sortir
A40: TC-HARGA-BELI-003 | B40: HARGA-BELI | C40: 3 | D40: Kode grade duplikat/format tidak valid ditolak | E40: Form tambah grade terbuka. | F40: 1. Input kode_grade duplikat atau >3 karakter/tidak diawali huruf. 2. Simpan. | G40: Validasi menolak input tidak valid. | H40: Tidak dieksekusi pada sesi ini. | I40: Not Executed | J40: P1 | K40: Admin Sortir
A41: TC-HARGA-BELI-004 | B41: HARGA-BELI | C41: 4 | D41: Nonaktifkan grade -> tidak muncul di transaksi baru, transaksi lama tetap snapshot lama | E41: Grade aktif dgn riwayat transaksi tersedia. | F41: 1. Nonaktifkan status grade. 2. Cek dropdown grade di transaksi baru (Sortir). 3. Cek transaksi lama yang memakai grade tsb. | G41: Grade nonaktif hilang dari opsi baru; transaksi lama tetap menampilkan harga snapshot lama. | H41: Tidak dieksekusi pada sesi ini. | I41: Not Executed | J41: P0 | K41: Admin Sortir
A42: TC-HARGA-BELI-005 | B42: HARGA-BELI | C42: 5 | D42: Perubahan harga grade TIDAK mengubah retroaktif transaksi selesai (snapshot) | E42: Transaksi selesai dengan grade tertentu tersedia. | F42: 1. Ubah harga_per_kg grade yang dipakai transaksi lama. 2. Cek apakah harga di transaksi lama ikut berubah. | G42: Harga di transaksi lama TIDAK berubah (harga di-snapshot saat transaksi dibuat) - KRITIKAL KEUANGAN. | H42: Tidak dieksekusi langsung sebagai skenario ubah-harga-lalu-cek-transaksi-lama. NAMUN, terverifikasi secara TIDAK LANGSUNG dan KUAT via pengamatan sepanjang pengujian: field harga_per_kg di-input manual per-bal pada tahap Sortir (Rp30.000/Rp31.000) dan nilai tsb konsisten dipakai persis di seluruh tahap berikutnya (Timbang, Kasir/Nota, Barang Gudang) tanpa berubah - mengindikasikan arsitektur snapshot-per-bal memang diterapkan, konsisten dgn kode financialCalculations.ts yang eksplisit menggunakan bal.harga_per_kg (bukan harga master terkini) sbg sumber kalkulasi. | I42: Not Executed | J42: P0 | K42: Admin Sortir | M42: Kode di src/utils/financialCalculations.ts baris 44 & 108-109 & 184 mengkonfirmasi desain snapshot-first (fallback ke harga master HANYA jika field harga_per_kg bal kosong). Rekomendasi: tetap lakukan uji eksplisit ubah-harga-retroaktif pada siklus berikutnya untuk kepastian 100%.
A43: TC-HARGA-BELI-006 | B43: HARGA-BELI | C43: 6 | D43: rate_potongan_per_bal & berat_standar_kg per grade dipakai benar di Kasir | E43: Grade dgn rate_potongan_per_bal/berat_standar_kg custom tersedia. | F43: 1. Buat transaksi dgn grade tsb. 2. Verifikasi kalkulasi Kasir memakai rate custom. | G43: Kalkulasi memakai rate sesuai master grade. | H43: Tidak dieksekusi pada sesi ini; pada data demo yang digunakan, potongan kuli/tali bersifat konstan universal Rp7.000/Rp3.000 (tidak per-grade), sehingga skenario rate custom per-grade tidak teruji. | I43: Not Executed | J43: P0 | K43: Admin Sortir
A44: TC-HARGA-BELI-007 | B44: HARGA-BELI | C44: 7 | D44: Tanggal berlaku vs berakhir - rentang tumpang tindih antar entri harga grade sama | E44: Beberapa entri harga utk grade sama dgn tanggal berbeda. | F44: 1. Buat 2 entri harga utk grade sama dgn rentang tanggal tumpang tindih. 2. Amati penanganan sistem. | G44: Sistem menangani/menolak/memberi peringatan tumpang tindih. | H44: Tidak dieksekusi pada sesi ini. | I44: Not Executed | J44: P1 | K44: Admin Sortir
A45: TC-HARGA-JUAL-001 | B45: HARGA-JUAL | C45: 1 | D45: CRUD kode harga jual (kode, harga_jual, tanggal_berlaku) | E45: Login admin_pengiriman/superadmin. | F45: 1. Buka Master Harga Jual Pabrik. 2. Tambah/ubah/hapus entri. | G45: CRUD berjalan normal. | H45: Tidak dieksekusi sebagai CRUD langsung. NAMUN, modul ini teramati berisi 41 kode harga jual siap pakai (kode 40-80, Rp40.000-Rp80.000/kg) dan berhasil DIGUNAKAN (bukan diubah) secara fungsional saat pembuatan Surat Jalan DO (KIRIM-005): kode '45 (Rp45.000/kg)' diterapkan massal ke 3 bal dan nilainya terkalkulasi benar (153kg x Rp45.000 = Rp6.885.000). | I45: Not Executed | J45: P0 | K45: Admin Pengiriman | M45: Penggunaan data existing (read) berhasil; operasi tulis (create/update/delete) master harga jual tidak diuji.
A46: TC-HARGA-JUAL-002 | B46: HARGA-JUAL | C46: 2 | D46: Nonaktifkan harga jual -> histori Pengiriman lama tetap terhubung | E46: Kode harga jual dgn histori pengiriman tersedia. | F46: 1. Nonaktifkan suatu kode harga jual. 2. Cek opsi baru di Pengiriman. 3. Cek histori pengiriman lama. | G46: Kode nonaktif hilang dari opsi baru; histori lama tetap terhubung ke kode lama. | H46: Tidak dieksekusi pada sesi ini. | I46: Not Executed | J46: P0 | K46: Admin Pengiriman
A47: TC-HARGA-JUAL-003 | B47: HARGA-JUAL | C47: 3 | D47: Harga jual dipakai benar di kalkulasi profit | E47: DO dgn kode harga jual tertentu tersedia. | F47: 1. Buat/lihat DO dgn kode harga jual X. 2. Verifikasi Total Penjualan di Dashboard = netto x harga_jual X. | G47: Kalkulasi profit memakai harga jual yang benar. | H47: TERVERIFIKASI PENUH via skenario end-to-end nyata (lihat KIRIM-010 & DASH-001): DO KIRIM-005 memakai kode harga jual '45' (Rp45.000/kg) untuk 153kg -> Total Penjualan Dashboard menunjukkan tepat Rp6.885.000 (153 x 45.000), dan Keuntungan Bersih Rp2.241.000 (6.885.000 - 4.644.000) dgn margin 32.5% - seluruhnya matematis akurat sesuai formula §12.1. | I47: Pass | J47: P0 | K47: Admin Pengiriman/Superadmin
A48: TC-MASTER-BRG-001 | B48: MASTER-BRG | C48: 1 | D48: CRUD master grade/kategori/varietas barang | E48: Login superadmin/admin_sortir, modul Master Barang. | F48: 1. Lakukan create/edit/delete pada master barang. | G48: CRUD berjalan normal. | H48: Tidak dieksekusi pada sesi ini - modul Master Barang (modul-2-barang) tidak dikunjungi karena tidak muncul eksplisit pada set modul yang diuji (fokus waktu pada alur transaksi kritikal). | I48: Not Executed | J48: P1 | K48: Admin Sortir
A49: TC-MASTER-BRG-002 | B49: MASTER-BRG | C49: 2 | D49: berat_standar_kg & lokasi_default_gudang terisi otomatis saat dipakai modul lain | E49: Master barang dgn default value tersedia. | F49: 1. Gunakan master barang tsb di modul lain (Sortir/Timbang). 2. Cek auto-fill default value. | G49: Default value terisi otomatis dgn benar. | H49: Tidak dieksekusi pada sesi ini. | I49: Not Executed | J49: P1 | K49: Admin Sortir
...

Sheet Defect Log
A1: Defect ID | B1: Judul | C1: Severity | D1: Modul Terkait | E1: Test Case Terkait | F1: File/Lokasi Kode | G1: Deskripsi | H1: Langkah Reproduksi | I1: Expected | J1: Actual | K1: Dampak Bisnis | L1: Rekomendasi | M1: Status
A2: DEF-001 | B2: Bypass autentikasi total pada localStorage kosong - auto-login sebagai Super Admin tanpa kredensial | C2: Blocker | D2: Autentikasi & Sesi | E2: TC-AUTH-011 | F2: src/utils/storage.ts (fungsi loadCurrentUser, baris 173-180) | G2: Ketika localStorage benar-benar kosong (mensimulasikan pengunjung pertama kali / browser baru, bukan hanya 'sesi hilang' seperti diasumsikan dokumen persiapan), aplikasi TIDAK PERNAH menampilkan halaman Login. Sistem langsung melakukan auto-login sebagai user Super Admin aktif pertama dengan akses penuh ke seluruh 19 modul, tanpa meminta kredensial apapun. | H2: 1. Buka aplikasi di browser (kondisi apapun). 2. Buka DevTools Console, jalankan: localStorage.clear() 3. Reload halaman / navigasi ulang ke URL aplikasi. 4. Amati bahwa aplikasi langsung menampilkan Dasbor Menu Utama sebagai Super Admin (Bpk. H. Rahmat Sulistyo), BUKAN halaman Login. | I2: Halaman Login harus ditampilkan, mewajibkan input kredensial yang valid sebelum akses diberikan. | J2: Akses penuh Super Admin diberikan secara otomatis tanpa kredensial apapun. | K2: KRITIKAL. Siapapun yang membuka aplikasi di browser manapun (bahkan tanpa pernah login sebelumnya) otomatis mendapat akses penuh Super Admin - termasuk Kelola User, Audit Trail, dan seluruh data operasional & finansial. Ini jauh lebih parah dari 'auto-heal setelah sesi hilang' yang diasumsikan dokumen §2, karena berlaku juga pada kondisi benar-benar belum pernah ada sesi (first-time visit). Risiko sangat tinggi jika sistem diakses di jaringan publik/perangkat bersama. | L2: Hapus/ubah logika fallback pada loadCurrentUser(): auto-heal HANYA boleh berlaku jika sebelumnya memang ada sesi user yang valid tersimpan dan hilang karena error teknis (bukan pada kondisi localStorage benar-benar kosong/first-time). Pada kondisi tidak ada data sesi sama sekali, harus SELALU menampilkan Login View. Wajib diperbaiki sebelum go-live produksi. | M2: Open
A3: DEF-002 | B3: Potongan Ganti Tikar (Rp75.000) tidak ikut dijumlahkan ke Total Potongan & Harga Final - petani berpotensi dibayar lebih besar | C3: Critical | D3: Kasir (Perhitungan Finansial) | E3: TC-KASIR-003, TC-KASIR-004, TC-KASIR-006, TC-KASIR-007, TC-KASIR-011 | F3: Diduga pada logika agregasi total_potongan di alur Timbangan/Kasir (TimbanganPageView.tsx / PembayaranKasirModal.tsx) | G3: Saat sebuah bal ditandai 'Ada Ganti Tikar' pada tahap Timbang, nilai potongan tikar (Rp75.000) DITAMPILKAN dengan benar secara itemisasi pada 'Rincian Potongan Biaya' di Nota Timbang & Kasir (baris terpisah 'Biaya Ganti Tikar'), namun nilai tersebut TIDAK IKUT DIJUMLAHKAN ke 'TOTAL POTONGAN KESELURUHAN' yang sebenarnya dipakai untuk menghitung nominal pembayaran tunai ke petani. Akibatnya harga_final yang dibayarkan ke petani LEBIH BESAR dari seharusnya, sebesar nilai potongan tikar yang hilang. | H3: 1. Login sebagai Admin Sortir, buat transaksi baru dengan minimal 1 bal. 2. Login sebagai Admin Timbang, timbang bal tersebut dan centang 'Ada Ganti Tikar?'. 3. Login sebagai Admin Kasir, buka Nota Timbang & Kasir Pembayaran untuk transaksi tsb. 4. Bandingkan penjumlahan manual baris 'Rincian Potongan Biaya' (Kuli + Tali + Tikar) dengan angka 'TOTAL POTONGAN KESELURUHAN' yang tertera. | I3: TOTAL POTONGAN KESELURUHAN = Biaya Kuli + Biaya Tali + Biaya Ganti Tikar (jika berlaku). Pada kasus uji: Rp21.000 + Rp9.000 + Rp75.000 = Rp105.000. | J3: TOTAL POTONGAN KESELURUHAN hanya menampilkan Rp30.000 (=Rp21.000+Rp9.000), mengabaikan Rp75.000 Biaya Ganti Tikar yang sudah benar ditampilkan di baris itemisasi tepat di atasnya pada dokumen yang sama. Harga Final yang dibayar ke petani (Rp4.614.000) lebih besar Rp75.000 dari nilai yang seharusnya (Rp4.539.000). | K3: Berdampak LANGSUNG pada akurasi kas & laporan keuangan perusahaan - setiap bal dengan Ganti Tikar menyebabkan kelebihan bayar Rp75.000 ke petani, terakumulasi signifikan pada skala operasional harian. Bug ini juga terwariskan ke Nota Timbang resmi (surat bukti timbang) yang dicetak & diserahkan ke petani sebagai dasar hukum pembayaran, sehingga berdampak legal-formal, bukan hanya kosmetik UI. | L3: Prioritas TERTINGGI untuk diperbaiki sebelum go-live. Audit ulang seluruh alur agregasi total_potongan pada TimbanganPageView.tsx dan PembayaranKasirModal.tsx untuk memastikan komponen potongan_tikar konsisten disertakan di semua titik kalkulasi (per-bal subtotal_bersih, total transaksi, dan nota cetak). Tambahkan unit test regresi khusus untuk skenario ganti_tikar=true guna mencegah regresi di masa depan. | M3: Open
A4: DEF-003 | B4: Audit Trail tidak menampilkan data existing saat modul pertama dibuka - harus klik 'Segarkan' manual | C4: Major | D4: Audit Trail | E4: TC-AUDIT-002 | F4: Modul Audit Trail (Manajemen Pengguna > Audit Trail & Log Aktivitas) | G4: Saat superadmin membuka modul Audit Trail untuk pertama kali dalam suatu sesi, tampilan menunjukkan pesan 'Belum ada aktivitas audit yang tercatat' (0 rekaman) - meskipun sesungguhnya SUDAH ADA rekaman audit tersimpan (terbukti setelah tombol 'Segarkan' diklik, 8 rekaman langsung muncul dengan lengkap & akurat). Data pencatatan itu sendiri BENAR; masalahnya murni pada tidak adanya auto-load/auto-fetch saat komponen pertama kali dirender. | H4: 1. Lakukan beberapa aksi kritikal (mis. buat transaksi, timbang bal, bayar kasir). 2. Login sebagai superadmin, navigasi ke Manajemen Pengguna > tab 'Audit Trail & Log Aktivitas'. 3. Amati kondisi tampilan SEBELUM mengklik tombol apapun. 4. Klik tombol 'Segarkan' dan amati perubahan. | I4: Rekaman audit yang sudah ada langsung tampil otomatis saat modul dibuka, tanpa perlu aksi manual tambahan. | J4: Tampilan menunjukkan 'Belum ada aktivitas audit yang tercatat' sampai tombol 'Segarkan' diklik manual, baru kemudian 8 rekaman yang sebenarnya sudah ada muncul. | K4: Berisiko MENYESATKAN superadmin yang melakukan pengecekan audit cepat (mis. saat investigasi insiden) untuk menyimpulkan secara keliru bahwa 'tidak ada aktivitas mencurigakan tercatat', padahal datanya sebenarnya ada. Ini melemahkan nilai audit trail sebagai alat pengawasan keamanan & akuntabilitas. | L4: Pastikan komponen Audit Trail melakukan fetch/load data audit secara otomatis pada saat mount (useEffect tanpa dependency kosong / pemanggilan awal), bukan hanya reaktif terhadap klik tombol 'Segarkan'. | M4: Open
A5: DEF-004 | B5: Audit log field 'Status Pembayaran' before-value tercatat sebagai string 'undefined', bukan status sebelumnya yang sebenarnya | C5: Minor | D5: Audit Trail | E5: TC-AUDIT-003 | F5: Logika pencatatan rincian_perubahan pada aksi pembayaran Kasir | G5: Pada entri audit KOREKSI yang dihasilkan saat transaksi dibayar lunas via Kasir, detail rincian_perubahan untuk field status pembayaran menampilkan 'Status bayar: undefined -> lunas' - nilai 'before' seharusnya adalah status sebelumnya yang valid (mis. 'belum_lunas' atau 'kredit'), bukan literal string/nilai kosong 'undefined'. | H5: 1. Selesaikan transaksi hingga status 'Siap Bayar'. 2. Proses pembayaran via Kasir (Cairkan Cash). 3. Buka Audit Trail sebagai superadmin, cari entri KOREKSI terkait transaksi tsb. 4. Amati baris 'Status bayar' pada rincian perubahan. | I5: Status bayar: belum_lunas -> lunas (atau nilai status sebelumnya yang valid dan bermakna). | J5: Status bayar: undefined -> lunas | K5: Rendah - hanya mengurangi kejelasan/kelengkapan jejak audit untuk satu field spesifik; field numerik lain (Netto, Nilai) pada entri yang sama tercatat lengkap & akurat. | L5: Pastikan nilai status_pembayaran lama diambil dari state transaksi SEBELUM mutasi diterapkan, bukan dari referensi objek yang sudah termutasi, saat membangun payload rincian_perubahan. | M5: Open
A6: DEF-005 | B6: Teks deskripsi modul 'Pengiriman Sample' pada Menu Akses Anda bersifat statis/hardcoded, tidak sinkron dengan data real | C6: Minor / Cosmetic | D6: Home / Menu Akses Anda | E6: TC-SAMPLE-001 | F6: Deskripsi kartu modul pada Dasbor Menu Utama (kemungkinan Sidebar.tsx / konstanta deskripsi modul) | G6: Saat login sebagai admin_pengiriman pada kondisi data belum ada satupun batch sample (counter modul menunjukkan '0'), teks keterangan pada kartu modul 'Pengiriman Sample' di 'Menu Akses Anda' tetap menampilkan narasi kondisi tertentu (mis. '3 Sedang Pengiriman, 1 Sedang Berangkat, 4 Selesai') yang tidak sesuai dengan data aktual (0 batch). | H6: 1. Login sebagai admin_pengiriman pada kondisi data sample kosong (badge counter '0' pada menu 'Pengiriman Sample'). 2. Amati kolom 'Keterangan & Cakupan Fungsi' pada baris modul Pengiriman Sample di tabel 'Menu Akses Anda'. | I6: Deskripsi mencerminkan kondisi data real-time, atau berupa deskripsi generik netral yang tidak menyebutkan angka spesifik jika tidak dihitung secara dinamis. | J6: Deskripsi menampilkan narasi angka spesifik yang tidak cocok dengan counter badge modul yang sesungguhnya (0). | K6: Rendah - berpotensi membingungkan pengguna sekilas mengenai kondisi data terkini, namun tidak berdampak fungsional (badge counter di sebelah nama modul tetap akurat). | L6: Hitung teks keterangan modul secara dinamis dari data aktual, atau ganti dengan deskripsi generik yang tidak bergantung pada angka statistik real-time. | M6: Open
A7: DEF-006 | B7: Kode mati (dead code) TransaksiFormModal.tsx memiliki formula potongan yang tidak sesuai dokumentasi | C7: Minor / Code Hygiene | D7: Transaksi (kode tidak terpakai) | E7: - | F7: src/components/transaksi/TransaksiFormModal.tsx & TransaksiManagement.tsx | G7: Ditemukan jalur pembuatan transaksi alternatif (TransaksiFormModal via TransaksiManagement) yang TIDAK diroutekan di manapun pada App.tsx (modul-0-transaksi secara aktual dirender oleh KasirPageView, bukan TransaksiManagement) - sehingga kode ini tidak dapat dijangkau pengguna manapun (dead code). Kode ini memiliki formula potongan yang BERBEDA dari spesifikasi dokumen: potongan_kuli=7000/bal (benar), namun TIDAK ADA potongan_tali sama sekali, dan potongan_tikar dihitung flat Rp2.000/bal (bukan Rp75.000 kondisional sesuai ganti_tikar seperti pada jalur aktif Proses2TimbangModal.tsx). | H7: 1. Review kode src/components/transaksi/TransaksiFormModal.tsx baris 325-326. 2. Bandingkan dengan formula resmi §12.1 dokumen dan implementasi aktif di Proses2TimbangModal.tsx. 3. Konfirmasi via App.tsx bahwa modul-0-transaksi dirender oleh KasirPageView (bukan TransaksiManagement), sehingga kode ini tidak live. | I7: Tidak ada kode tidak terpakai dengan formula bisnis yang menyimpang dari dokumentasi resmi tersisa di codebase. | J7: Kode dead/unreachable ini tetap ada di codebase dengan formula yang salah, berisiko diaktifkan kembali secara tidak sengaja di masa depan (mis. saat refactor routing) tanpa disadari perbedaan formulanya. | K7: Tidak ada dampak langsung ke pengguna saat ini (kode tidak dapat dijangkau via UI manapun). Risiko LATEN jika kode ini di-reroute/diaktifkan kembali tanpa audit ulang formula. | L7: Hapus kode tidak terpakai ini (TransaksiFormModal.tsx, TransaksiManagement.tsx) jika memang tidak lagi diperlukan, atau jika berencana diaktifkan kembali, perbarui dahulu formulanya agar konsisten dengan Proses2TimbangModal.tsx dan dokumen §12.1. | M7: Open
A8: DEF-007 | B8: Password user disimpan plaintext (bukan hash) - risiko keamanan yang sudah diketahui sesuai dokumen | C8: Critical (Accepted Risk / Known Issue per dokumen) | D8: Manajemen User / Arsitektur Sistem | E8: TC-USER-008, TC-NF-SEC-001 | F8: src/utils/storage.ts, src/data/initialUserData.ts (field 'password' pada tipe User) | G8: Password seluruh user (termasuk superadmin) disimpan sebagai teks biasa (plaintext) pada objek User di localStorage, tanpa hashing/enkripsi. Ini bukan temuan baru - dokumen persiapan pengujian (§2, §9.6, §12.4) sudah secara eksplisit mengidentifikasi ini sebagai risiko yang diketahui dan meminta agar dicatat sebagai temuan, bukan diverifikasi sebagai fitur normal. | H8: 1. Review kode src/utils/storage.ts dan src/data/initialUserData.ts. 2. Amati struktur objek User yang menyertakan field 'password' berisi nilai plaintext (mis. 'admin123'). | I8: Password idealnya di-hash (mis. bcrypt/argon2) sebelum disimpan, bahkan pada arsitektur client-only. | J8: Password tersimpan sebagai plaintext di localStorage. | K8: Jika perangkat/browser/localStorage bocor (mis. melalui ekstensi browser berbahaya, akses fisik ke perangkat, atau backup file yang tidak diamankan), seluruh kredensial staf & superadmin dapat langsung terbaca tanpa perlu cracking. | L8: Sesuai rekomendasi dokumen §12.4: terapkan hashing password sebelum sistem dipakai di lingkungan produksi nyata, idealnya seiring migrasi ke backend server yang mendukung hashing & salting yang layak. | M8: Accepted Risk (per instruksi dokumen - dikomunikasikan ke Product Owner)
A9: DEF-008 | B9: Tombol 'Akses Cepat Pengujian Role (1-Klik)' dan info 'Default pass' tampil langsung di halaman Login produksi | C9: Informational | D9: Autentikasi & Sesi | E9: TC-AUTH-001 | F9: Komponen LoginView | G9: Halaman Login menampilkan panel 'AKSES CEPAT PENGUJIAN ROLE (1-KLIK)' berisi 6 tombol yang langsung login sebagai role tertentu tanpa perlu mengetik password, serta teks 'Default pass: admin123' di sebelah checkbox 'Ingat Sesi'. Fitur ini sangat membantu untuk mempercepat pengujian QA (dan memang dimanfaatkan secara ekstensif pada sesi pengujian ini), namun merupakan risiko keamanan serius apabila terbawa ke lingkungan produksi tanpa dinonaktifkan. | H9: 1. Buka halaman Login (logout terlebih dahulu jika perlu). 2. Amati panel 'AKSES CEPAT PENGUJIAN ROLE (1-KLIK)' dan teks 'Default pass: admin123' yang tampil langsung tanpa perlu login. | I9: Fitur kemudahan uji semacam ini idealnya hanya aktif pada environment development/staging (mis. dikontrol oleh flag build/env), tidak muncul pada build produksi. | J9: Fitur tampil aktif pada build yang diuji (Build: 2026-08-REV3, 'Desktop Standalone v2.4'). | K9: Jika terbawa ke produksi, siapapun yang mengakses halaman login dapat login sebagai role manapun (termasuk Super Admin) hanya dengan 1 klik, tanpa mengetahui password sama sekali - menghilangkan seluruh nilai autentikasi. | L9: Bungkus fitur ini dengan flag environment (mis. import.meta.env.DEV) agar otomatis tidak dirender pada build produksi. Pastikan proses build/release memverifikasi fitur ini tidak aktif sebelum go-live. | M9: Open

Sheet Ringkasan Eksekusi
A1: RINGKASAN EKSEKUSI PENGUJIAN PER MODUL
A3: Kode Modul | B3: Nama Modul | C3: Total TC | D3: Pass | E3: Fail | F3: Blocked | G3: Not Executed
A4: AUTH | B4: Autentikasi & Sesi | C4: =COUNTIF('Test Case Detail'!$B$2:$B$150,$A4) | D4: =COUNTIFS('Test Case Detail'!$B$2:$B$150,$A4,'Test Case Detail'!$I$2:$I$150,"Pass") | E4: =COUNTIFS('Test Case Detail'!$B$2:$B$150,$A4,'Test Case Detail'!$I$2:$I$150,"Fail") | F4: =COUNTIFS('Test Case Detail'!$B$2:$B$150,$A4,'Test Case Detail'!$I$2:$I$150,"Blocked") | G4: =COUNTIFS('Test Case Detail'!$B$2:$B$150,$A4,'Test Case Detail'!$I$2:$I$150,"Not Executed")
A5: RBAC | B5: RBAC | C5: =COUNTIF('Test Case Detail'!$B$2:$B$150,$A5) | D5: =COUNTIFS('Test Case Detail'!$B$2:$B$150,$A5,'Test Case Detail'!$I$2:$I$150,"Pass") | E5: =COUNTIFS('Test Case Detail'!$B$2:$B$150,$A5,'Test Case Detail'!$I$2:$I$150,"Fail") | F5: =COUNTIFS('Test Case Detail'!$B$2:$B$150,$A5,'Test Case Detail'!$I$2:$I$150,"Blocked") | G5: =COUNTIFS('Test Case Detail'!$B$2:$B$150,$A5,'Test Case Detail'!$I$2:$I$150,"Not Executed")
A6: PETANI | B6: Manajemen Petani | C6: =COUNTIF('Test Case Detail'!$B$2:$B$150,$A6) | D6: =COUNTIFS('Test Case Detail'!$B$2:$B$150,$A6,'Test Case Detail'!$I$2:$I$150,"Pass") | E6: =COUNTIFS('Test Case Detail'!$B$2:$B$150,$A6,'Test Case Detail'!$I$2:$I$150,"Fail") | F6: =COUNTIFS('Test Case Detail'!$B$2:$B$150,$A6,'Test Case Detail'!$I$2:$I$150,"Blocked") | G6: =COUNTIFS('Test Case Detail'!$B$2:$B$150,$A6,'Test Case Detail'!$I$2:$I$150,"Not Executed")
A7: HARGA-BELI | B7: Master Harga Beli | C7: =COUNTIF('Test Case Detail'!$B$2:$B$150,$A7) | D7: =COUNTIFS('Test Case Detail'!$B$2:$B$150,$A7,'Test Case Detail'!$I$2:$I$150,"Pass") | E7: =COUNTIFS('Test Case Detail'!$B$2:$B$150,$A7,'Test Case Detail'!$I$2:$I$150,"Fail") | F7: =COUNTIFS('Test Case Detail'!$B$2:$B$150,$A7,'Test Case Detail'!$I$2:$I$150,"Blocked") | G7: =COUNTIFS('Test Case Detail'!$B$2:$B$150,$A7,'Test Case Detail'!$I$2:$I$150,"Not Executed")
A8: HARGA-JUAL | B8: Master Harga Jual | C8: =COUNTIF('Test Case Detail'!$B$2:$B$150,$A8) | D8: =COUNTIFS('Test Case Detail'!$B$2:$B$150,$A8,'Test Case Detail'!$I$2:$I$150,"Pass") | E8: =COUNTIFS('Test Case Detail'!$B$2:$B$150,$A8,'Test Case Detail'!$I$2:$I$150,"Fail") | F8: =COUNTIFS('Test Case Detail'!$B$2:$B$150,$A8,'Test Case Detail'!$I$2:$I$150,"Blocked") | G8: =COUNTIFS('Test Case Detail'!$B$2:$B$150,$A8,'Test Case Detail'!$I$2:$I$150,"Not Executed")
A9: MASTER-BRG | B9: Master Barang | C9: =COUNTIF('Test Case Detail'!$B$2:$B$150,$A9) | D9: =COUNTIFS('Test Case Detail'!$B$2:$B$150,$A9,'Test Case Detail'!$I$2:$I$150,"Pass") | E9: =COUNTIFS('Test Case Detail'!$B$2:$B$150,$A9,'Test Case Detail'!$I$2:$I$150,"Fail") | F9: =COUNTIFS('Test Case Detail'!$B$2:$B$150,$A9,'Test Case Detail'!$I$2:$I$150,"Blocked") | G9: =COUNTIFS('Test Case Detail'!$B$2:$B$150,$A9,'Test Case Detail'!$I$2:$I$150,"Not Executed")
A10: SORTIR | B10: Proses 1 - Sortir | C10: =COUNTIF('Test Case Detail'!$B$2:$B$150,$A10) | D10: =COUNTIFS('Test Case Detail'!$B$2:$B$150,$A10,'Test Case Detail'!$I$2:$I$150,"Pass") | E10: =COUNTIFS('Test Case Detail'!$B$2:$B$150,$A10,'Test Case Detail'!$I$2:$I$150,"Fail") | F10: =COUNTIFS('Test Case Detail'!$B$2:$B$150,$A10,'Test Case Detail'!$I$2:$I$150,"Blocked") | G10: =COUNTIFS('Test Case Detail'!$B$2:$B$150,$A10,'Test Case Detail'!$I$2:$I$150,"Not Executed")
A11: TIMBANG | B11: Proses 2 - Timbang | C11: =COUNTIF('Test Case Detail'!$B$2:$B$150,$A11) | D11: =COUNTIFS('Test Case Detail'!$B$2:$B$150,$A11,'Test Case Detail'!$I$2:$I$150,"Pass") | E11: =COUNTIFS('Test Case Detail'!$B$2:$B$150,$A11,'Test Case Detail'!$I$2:$I$150,"Fail") | F11: =COUNTIFS('Test Case Detail'!$B$2:$B$150,$A11,'Test Case Detail'!$I$2:$I$150,"Blocked") | G11: =COUNTIFS('Test Case Detail'!$B$2:$B$150,$A11,'Test Case Detail'!$I$2:$I$150,"Not Executed")
A12: KASIR | B12: Proses 3 - Kasir | C12: =COUNTIF('Test Case Detail'!$B$2:$B$150,$A12) | D12: =COUNTIFS('Test Case Detail'!$B$2:$B$150,$A12,'Test Case Detail'!$I$2:$I$150,"Pass") | E12: =COUNTIFS('Test Case Detail'!$B$2:$B$150,$A12,'Test Case Detail'!$I$2:$I$150,"Fail") | F12: =COUNTIFS('Test Case Detail'!$B$2:$B$150,$A12,'Test Case Detail'!$I$2:$I$150,"Blocked") | G12: =COUNTIFS('Test Case Detail'!$B$2:$B$150,$A12,'Test Case Detail'!$I$2:$I$150,"Not Executed")
A13: SAMPLE | B13: Sample & Evaluasi Buyer | C13: =COUNTIF('Test Case Detail'!$B$2:$B$150,$A13) | D13: =COUNTIFS('Test Case Detail'!$B$2:$B$150,$A13,'Test Case Detail'!$I$2:$I$150,"Pass") | E13: =COUNTIFS('Test Case Detail'!$B$2:$B$150,$A13,'Test Case Detail'!$I$2:$I$150,"Fail") | F13: =COUNTIFS('Test Case Detail'!$B$2:$B$150,$A13,'Test Case Detail'!$I$2:$I$150,"Blocked") | G13: =COUNTIFS('Test Case Detail'!$B$2:$B$150,$A13,'Test Case Detail'!$I$2:$I$150,"Not Executed")
A14: KIRIM | B14: Pengiriman / DO | C14: =COUNTIF('Test Case Detail'!$B$2:$B$150,$A14) | D14: =COUNTIFS('Test Case Detail'!$B$2:$B$150,$A14,'Test Case Detail'!$I$2:$I$150,"Pass") | E14: =COUNTIFS('Test Case Detail'!$B$2:$B$150,$A14,'Test Case Detail'!$I$2:$I$150,"Fail") | F14: =COUNTIFS('Test Case Detail'!$B$2:$B$150,$A14,'Test Case Detail'!$I$2:$I$150,"Blocked") | G14: =COUNTIFS('Test Case Detail'!$B$2:$B$150,$A14,'Test Case Detail'!$I$2:$I$150,"Not Executed")
A15: STATUS-BATCH | B15: Status Batch Pengiriman | C15: =COUNTIF('Test Case Detail'!$B$2:$B$150,$A15) | D15: =COUNTIFS('Test Case Detail'!$B$2:$B$150,$A15,'Test Case Detail'!$I$2:$I$150,"Pass") | E15: =COUNTIFS('Test Case Detail'!$B$2:$B$150,$A15,'Test Case Detail'!$I$2:$I$150,"Fail") | F15: =COUNTIFS('Test Case Detail'!$B$2:$B$150,$A15,'Test Case Detail'!$I$2:$I$150,"Blocked") | G15: =COUNTIFS('Test Case Detail'!$B$2:$B$150,$A15,'Test Case Detail'!$I$2:$I$150,"Not Executed")
... A24: NF-A11Y | B24: NF - Aksesibilitas | C24: =COUNTIF('Test Case Detail'!$B$2:$B$150,$A24) | D24: =COUNTIFS('Test Case Detail'!$B$2:$B$150,$A24,'Test Case Detail'!$I$2:$I$150,"Pass") | E24: =COUNTIFS('Test Case Detail'!$B$2:$B$150,$A24,'Test Case Detail'!$I$2:$I$150,"Fail") | F24: =COUNTIFS('Test Case Detail'!$B$2:$B$150,$A24,'Test Case Detail'!$I$2:$I$150,"Blocked") | G24: =COUNTIFS('Test Case Detail'!$B$2:$B$150,$A24,'Test Case Detail'!$I$2:$I$150,"Not Executed")
A25: TOTAL | B25: Seluruh Modul | C25: =SUM(C4:C24) | D25: =SUM(D4:D24) | E25: =SUM(E4:E24) | F25: =SUM(F4:F24) | G25: =SUM(G4:G24)
A27: STATUS KHUSUS PRIORITAS P0 (Blocker/Kritikal - wajib 100% Pass sebelum rilis, per Kriteria Keluar §9.2)
B28: Kategori | C28: Jumlah
B29: Total Test Case P0 | C29: =COUNTIF('Test Case Detail'!$J$2:$J$150,"P0")
B30: P0 - Pass | C30: =COUNTIFS('Test Case Detail'!$J$2:$J$150,"P0",'Test Case Detail'!$I$2:$I$150,"Pass")
B31: P0 - Fail | C31: =COUNTIFS('Test Case Detail'!$J$2:$J$150,"P0",'Test Case Detail'!$I$2:$I$150,"Fail")
B32: P0 - Blocked | C32: =COUNTIFS('Test Case Detail'!$J$2:$J$150,"P0",'Test Case Detail'!$I$2:$I$150,"Blocked")
B33: P0 - Not Executed | C33: =COUNTIFS('Test Case Detail'!$J$2:$J$150,"P0",'Test Case Detail'!$I$2:$I$150,"Not Executed")
A35: RINGKASAN DEFECT (lihat sheet Defect Log utk detail lengkap)
B36: Severity | C36: Jumlah
B37: Blocker | C37: 1
B38: Critical | C38: 1
B39: Major | C39: 1
B40: Minor | C40: 1
B41: Minor / Cosmetic | C41: 1
B42: Minor / Code Hygiene | C42: 1
B43: Critical (Accepted Risk / Known Issue per dokumen) | C43: 1
B44: Informational | C44: 1
A46: KRITERIA MASUK (ENTRY CRITERIA) - dokumen §9.1
A47: npm run build (produksi) berhasil tanpa error | D47: TERPENUHI - build sukses, output dist/ ter-generate (peringatan ukuran chunk >500kB bersifat non-blocking, bukan error)
A48: npm run lint (tsc --noEmit) lulus tanpa error TypeScript | D48: TERPENUHI - 0 error TypeScript
A49: Environment uji tersedia dgn data demo ter-reset | D49: TERPENUHI - dev server berjalan dgn data demo awal (34 petani, 41 kode grade, dst)
A50: Dokumen & skenario turunan direview QA Lead/Product Owner | D50: BELUM - dokumen test case ini adalah HASIL dari proses tsb, menunggu review & sign-off Product Owner (lihat sheet Sign-off)

Sheet Traceability Matrix
A1: # | B1: Tahapan Critical User Journey (§5 Dokumen) | C1: Role Bertanggung Jawab | D1: Test Case Terkait | E1: Status Cakupan Sesi Ini
A2: 1 | B2: Petani datang & didaftarkan/dikenali via ID/barcode | C2: Admin Sortir | D2: TC-PETANI-001, TC-PETANI-002 | E2: DIUJI - petani baru berhasil dibuat dgn ID auto-generate & validasi field wajib
A3: 2 | B3: Kupon antrian dibuat & dipanggil | C3: Admin Sortir/Kasir | D3: TC-SORTIR-001 | E3: DIUJI - kupon KUP0001 dibuat otomatis saat transaksi Sortir dimulai
A4: 3 | B4: PROSES 1 - SORTIR: penentuan grade mutu per bal | C4: Admin Sortir | D4: TC-SORTIR-001 s/d 005 | E4: DIUJI PENUH - 3 bal multi-grade berhasil disortir & lanjut ke Timbang
A5: 4 | B5: PROSES 2 - TIMBANG: input bruto, hitung tara, netto otomatis | C5: Admin Timbang | D5: TC-TIMBANG-001 s/d 009 | E5: DIUJI PENUH termasuk boundary 49/50 & 59/60kg dan aturan khusus prefix SB
A6: 5 | B6: KASIR: validasi transaksi, hitung potongan, harga final, bayar, cetak nota | C6: Admin Kasir | D6: TC-KASIR-001 s/d 013 | E6: DIUJI PENUH - DITEMUKAN DEFECT KRITIKAL DEF-002 (potongan tikar tidak teragregasi)
A7: 6 | B7: Barang berstatus "di_gudang" tercatat sebagai stok | C7: Sistem/Auto | D7: TC-KASIR-013 | E7: DIUJI - 3 bal terverifikasi status "Di Gudang" di Inventaris Bal Gudang
A8: 7a | B8: (Opsional) Kirim SAMPLE ke buyer utk evaluasi | C8: Admin Sortir/Pengiriman | D8: TC-SAMPLE-001 s/d 009 | E8: TIDAK DIUJI - di luar cakupan waktu sesi ini, modul dikunjungi namun tanpa data
A9: 7b | B9: Update Master Harga Jual berdasarkan hasil deal | C9: Admin Pengiriman | D9: TC-HARGA-JUAL-001 s/d 003 | E9: SEBAGIAN - penggunaan (read) master harga jual terverifikasi via KIRIM-005; CRUD tidak diuji
A10: 8 | B10: PENGIRIMAN: konsolidasi bal, assign sopir/kendaraan, cetak Surat Jalan | C10: Admin Pengiriman | D10: TC-KIRIM-001 s/d 007 | E10: DIUJI PENUH - DO berhasil dibuat, tervalidasi, dicetak dgn data akurat
A11: 9 | B11: Update status pengiriman s.d. "selesai"/"diterima" | C11: Admin Pengiriman | D11: TC-KIRIM-006 | E11: SEBAGIAN - status akhir "Terkirim DO" tercapai & memicu perubahan status_stok bal; transisi bertahap tidak teramati
A12: 10 | B12: Verifikasi profit di Dashboard Analitik & Laporan Pengiriman | C12: Kepala Gudang/Superadmin | D12: TC-KIRIM-010, TC-DASH-001, TC-DASH-008 | E12: DIUJI PENUH & AKURAT - Keuntungan Bersih Rp2.241.000 (32,5% margin) matematis tepat
A13: 11 | B13: Verifikasi jejak audit (Audit Trail) mencatat setiap aksi penting | C13: Superadmin | D13: TC-AUDIT-001 s/d 006 | E13: DIUJI - data tercatat lengkap & akurat, NAMUN DITEMUKAN DEFECT MAYOR DEF-003 (tidak auto-load)

Sheet Sign-off
B2: CATATAN SIGN-OFF & REKOMENDASI RILIS
B4: Status Exit Criteria (§9.2 Dokumen)
B5: - 100% skenario P0 lulus (tidak boleh ada blocker terbuka): BELUM TERPENUHI - lihat sheet Ringkasan Eksekusi blok "Status Khusus Prioritas P0". Dari test case P0 yang BERHASIL dieksekusi, ditemukan 2 kegagalan langsung pada modul finansial/keamanan paling kritikal (DEF-001, DEF-002), dan mayoritas item P0 lain berstatus Not Executed karena keterbatasan waktu satu sesi pengujian.
B6: - >=95% skenario P1 lulus: BELUM DAPAT DIUKUR - proporsi P1 yang dieksekusi pada sesi ini masih terbatas; sebagian besar P1 tercatat Not Executed.
B7: - Tidak ada defect Critical/Blocker terbuka pada modul Kasir, Sortir-Timbang, Pengiriman, RBAC: TIDAK TERPENUHI - DEF-001 (Blocker, Autentikasi) dan DEF-002 (Critical, Kasir) MASIH TERBUKA.
B8: - Temuan keamanan (§7.4) sudah dikomunikasikan tertulis ke Product Owner: SEDANG DALAM PROSES - dokumen ini ADALAH bentuk komunikasi tertulis tsb; DEF-001, DEF-007, DEF-008 memerlukan keputusan eksplisit Product Owner.
B10: Rekomendasi
B11: - TIDAK DIREKOMENDASIKAN untuk rilis ke lingkungan produksi pada kondisi saat ini, hingga minimal DEF-001 (Blocker - celah otentikasi) dan DEF-002 (Critical - kesalahan finansial pembayaran petani) diperbaiki & diverifikasi ulang.
B12: - Modul kalkulasi profit pengiriman (financialCalculations.ts) TERBUKTI SANGAT ANDAL dan dapat dipercaya sebagai fondasi laporan keuangan eksekutif - tidak ditemukan cacat pada mesin kalkulasi ini.
B13: - Sangat direkomendasikan sesi pengujian lanjutan (regresi) dgn cakupan waktu lebih panjang utk menuntaskan 88 test case berstatus "Not Executed" pada dokumen ini, khususnya seluruh modul Sample (belum tersentuh sama sekali), CRUD Manajemen User, dan pengujian keamanan XSS menyeluruh di seluruh field teks bebas.
B14: - Sebelum go-live: (a) nonaktifkan fitur "Akses Cepat Pengujian Role" & tampilan default password pada build produksi (DEF-008); (b) terapkan hashing password (DEF-007); (c) jalankan pengujian localStorage-quota-exceeded & performa dataset besar yg belum sempat dieksekusi sesi ini.
B16: Tanda Tangan Persetujuan
B18: Peran | C18: Nama | D18: Tanda Tangan | E18: Tanggal
B19: QA Lead / Penyusun Laporan | C19: Claude (AI QA Engineer) - Automated Browser Testing | E19: 2026-09-13
B20: Product Owner
B21: Engineering Lead
